Workbook
Name IngredientList: 재료목록!$D$2:$D$42
Name MenuList: 재료목록!$F$2:$F$6
Name 꼬치오뎅: 범례!$D$2:$D$20
Name 닭강정: 범례!$A$2:$A$20
Name 떡볶이: 범례!$B$2:$B$14
Name 붕어빵: 범례!$C$2:$C$11

Sheet 사용안내
A1: 매입·판매수량 기록 템플릿 사용 안내
A3: 1) [매입현황_기록]에 매입이 발생할 때마다 한 줄씩 입력합니다. 날짜/메뉴/재료/수량/단가를 넣으면 금액은 자동 계산됩니다.
A4: 2) [판매수량_기록]에 일자별 판매수량을 입력합니다. 제품 단위가 다른 경우 [환산계수]에서 기준단위 환산 계수를 조정합니다.
A5: 3) [기간요약]에서 시작일/종료일만 입력하면, 메뉴별 매입액·판매량·(공통 배분 포함) 기준단위당 원가가 계산됩니다.
A6: 4) 공통(종이컵/비닐 등)은 [기간요약]의 배분비율(%)에 따라 메뉴별로 나눠집니다. (합계 100%)
A8: 주의: 메뉴와 재료가 맞지 않으면 [매입현황_기록]의 '체크'가 '불일치'로 표시됩니다.
A10: 기준일: 2026-01-03

Sheet 재료목록
A1: 메뉴 | B1: 재료명 | D1: 재료명(전체목록) | F1: 메뉴목록
A2: 닭강정 | B2: 염지닭 | D2: 10온스 종이컵 | F2: 닭강정
A3: 닭강정 | B3: 염지닭_택배비 | D3: 12cm꼬치 | F3: 떡볶이
A4: 닭강정 | B4: 비쉐프 만능강정소스(매콤달콤) | D4: 25cm꼬치 | F4: 꼬치오뎅
A5: 닭강정 | B5: 몬스터 골드강정소스(골드간장) | D5: M자비닐 | F5: 붕어빵
A6: 닭강정 | B6: 몬스터 강정파우더 | D6: 가래떡 | F6: 공통
A7: 닭강정 | B7: 왕짧짧 | D7: 고춧가루
A8: 닭강정 | B8: 해바라기씨유 | D8: 국간장
A9: 닭강정 | B9: 폐유 | D9: 꽃게다리
A10: 닭강정 | B10: 분태땅콩 | D10: 대봉투
A11: 닭강정 | B11: 치킨박스(중) | D11: 대파
A12: 닭강정 | B12: 치킨박스(소) | D12: 떡볶이 소스
A13: 닭강정 | B13: 뿌링클소스 | D13: 마라소스
A14: 닭강정 | B14: 엿 | D14: 모짜렐라치즈
A15: 닭강정 | B15: 마라소스 | D15: 몬스터 강정파우더
A16: 닭강정 | B16: 액상유자 | D16: 몬스터 골드강정소스(골드간장)
A17: 떡볶이 | B17: 밀떡볶이 | D17: 무
A18: 떡볶이 | B18: 밀떡볶이_택배비 | D18: 미원
... A42: 붕어빵 | B42: 반죽 | D42: 해바라기씨유
A43: 붕어빵 | B43: 팥
A44: 붕어빵 | B44: 슈크림
A45: 붕어빵 | B45: 모짜렐라치즈
A46: 붕어빵 | B46: 소봉투
A47: 붕어빵 | B47: LPG가스
A48: 붕어빵 | B48: 대봉투
A49: 공통 | B49: 10온스 종이컵
A50: 공통 | B50: 12cm꼬치
A51: 공통 | B51: M자비닐

Sheet 범례
A1: 닭강정 | B1: 떡볶이 | C1: 붕어빵 | D1: 꼬치오뎅
A2: 염지닭 | B2: 밀떡볶이 | C2: 반죽 | D2: 대파
A3: 염지닭_택배비 | B3: 밀떡볶이_택배비 | C3: 팥 | D3: 무
A4: 비쉐프 만능강정소스(매콤달콤) | B4: 쌀떡볶이 | C4: 슈크림 | D4: 꽃게다리
A5: 몬스터 골드강정소스(골드간장) | B5: 떡볶이 소스 | C5: 모짜렐라치즈 | D5: 상천어묵
A6: 몬스터 강정파우더 | B6: 상천어묵 | C6: 소봉투 | D6: 상천어묵_택배비
A7: 왕짧짧 | B7: 대파 | C7: 대봉투 | D7: 어묵용 스프
A8: 해바라기씨유 | B8: 비엔나소세지 | C8: LPG가스 | D8: 청양고추
A9: 폐유 | B9: 죽용용기(소) | C9: 10온스 종이컵 | D9: 쯔유
A10: 분태땅콩 | B10: 죽용용기(중) | C10: 12cm꼬치 | D10: 국간장
A11: 치킨박스(중) | B11: 10온스 종이컵 | C11: M자비닐 | D11: 진간장
A12: 치킨박스(소) | B12: 12cm꼬치 | D12: 양조간장
A13: 뿌링클소스 | B13: M자비닐 | D13: 고춧가루
A14: 엿 | D14: 미원
A15: 마라소스 | D15: 가래떡
A16: 액상유자 | D16: 25cm꼬치
A17: 10온스 종이컵 | D17: 10온스 종이컵
A18: 12cm꼬치 | D18: 12cm꼬치
A19: M자비닐 | D19: M자비닐

Sheet 매입현황_기록
A1: 날짜 | B1: 메뉴 | C1: 재료명 | D1: 공급처 | E1: 수량 | F1: 단가 | G1: 금액 | H1: 비고 | I1: 체크
A2: 45901 | B2: 닭강정 | C2: 몬스터 강정파우더 | D2: 소스몬스터 | E2: 2 | F2: 42500 | G2: =IF(OR(E2="",F2=""),"",E2*F2) -> 85000 | H2: 10KG | I2: =IF(OR(B2="",C2=""),"",IF(COUNTIFS(재료목록!$A$2:$A$51,B2,재료목록!$B$2:$B$51,C2)>0,"OK","불일치")) -> OK
A3: 45919 | B3: 붕어빵 | C3: LPG가스 | D3: 시내가스 | E3: 2 | F3: 48000 | G3: =IF(OR(E3="",F3=""),"",E3*F3) -> 96000 | I3: =IF(OR(B3="",C3=""),"",IF(COUNTIFS(재료목록!$A$2:$A$51,B3,재료목록!$B$2:$B$51,C3)>0,"OK","불일치")) -> OK
A4: 45922 | B4: 떡볶이 | C4: 쌀떡볶이 | D4: 농민식품 | E4: 2 | F4: 8000 | G4: =IF(OR(E4="",F4=""),"",E4*F4) -> 16000 | I4: =IF(OR(B4="",C4=""),"",IF(COUNTIFS(재료목록!$A$2:$A$51,B4,재료목록!$B$2:$B$51,C4)>0,"OK","불일치")) -> OK
A5: 45926 | B5: 붕어빵 | C5: 슈크림 | D5: 황금잉어빵세종 | E5: 1 | F5: 8500 | G5: =IF(OR(E5="",F5=""),"",E5*F5) -> 8500 | I5: =IF(OR(B5="",C5=""),"",IF(COUNTIFS(재료목록!$A$2:$A$51,B5,재료목록!$B$2:$B$51,C5)>0,"OK","불일치")) -> OK
A6: 45926 | B6: 붕어빵 | C6: 반죽 | D6: 황금잉어빵세종 | E6: 4 | F6: 13000 | G6: =IF(OR(E6="",F6=""),"",E6*F6) -> 52000 | I6: =IF(OR(B6="",C6=""),"",IF(COUNTIFS(재료목록!$A$2:$A$51,B6,재료목록!$B$2:$B$51,C6)>0,"OK","불일치")) -> OK
A7: 45926 | B7: 붕어빵 | C7: 팥 | D7: 황금잉어빵세종 | E7: 3 | F7: 8500 | G7: =IF(OR(E7="",F7=""),"",E7*F7) -> 25500 | I7: =IF(OR(B7="",C7=""),"",IF(COUNTIFS(재료목록!$A$2:$A$51,B7,재료목록!$B$2:$B$51,C7)>0,"OK","불일치")) -> OK
A8: 45926 | B8: 붕어빵 | C8: 슈크림 | D8: 황금잉어빵세종 | E8: 3 | F8: 8500 | G8: =IF(OR(E8="",F8=""),"",E8*F8) -> 25500 | I8: =IF(OR(B8="",C8=""),"",IF(COUNTIFS(재료목록!$A$2:$A$51,B8,재료목록!$B$2:$B$51,C8)>0,"OK","불일치")) -> OK
A9: 45930 | B9: 닭강정 | C9: 해바라기씨유 | D9: 가보유통 | E9: 2 | F9: 48000 | G9: =IF(OR(E9="",F9=""),"",E9*F9) -> 96000 | I9: =IF(OR(B9="",C9=""),"",IF(COUNTIFS(재료목록!$A$2:$A$51,B9,재료목록!$B$2:$B$51,C9)>0,"OK","불일치")) -> OK
A10: 45930 | B10: 닭강정 | C10: 폐유 | D10: 가보유통 | E10: 1 | F10: -22000 | G10: =IF(OR(E10="",F10=""),"",E10*F10) -> -22000 | I10: =IF(OR(B10="",C10=""),"",IF(COUNTIFS(재료목록!$A$2:$A$51,B10,재료목록!$B$2:$B$51,C10)>0,"OK","불일치")) -> OK
A11: 45931 | B11: 붕어빵 | C11: 반죽 | D11: 황금잉어빵세종 | E11: 1 | F11: 13000 | G11: =IF(OR(E11="",F11=""),"",E11*F11) -> 13000 | I11: =IF(OR(B11="",C11=""),"",IF(COUNTIFS(재료목록!$A$2:$A$51,B11,재료목록!$B$2:$B$51,C11)>0,"OK","불일치")) -> OK
A12: 45931 | B12: 붕어빵 | C12: 팥 | D12: 황금잉어빵세종 | E12: 1 | F12: 8500 | G12: =IF(OR(E12="",F12=""),"",E12*F12) -> 8500 | I12: =IF(OR(B12="",C12=""),"",IF(COUNTIFS(재료목록!$A$2:$A$51,B12,재료목록!$B$2:$B$51,C12)>0,"OK","불일치")) -> OK
A13: 45931 | B13: 붕어빵 | C13: 슈크림 | D13: 황금잉어빵세종 | E13: 1 | F13: 8500 | G13: =IF(OR(E13="",F13=""),"",E13*F13) -> 8500 | I13: =IF(OR(B13="",C13=""),"",IF(COUNTIFS(재료목록!$A$2:$A$51,B13,재료목록!$B$2:$B$51,C13)>0,"OK","불일치")) -> OK
A14: 45932 | B14: 붕어빵 | C14: 반죽 | D14: 황금잉어빵세종 | E14: 1 | F14: 13000 | G14: =IF(OR(E14="",F14=""),"",E14*F14) -> 13000 | I14: =IF(OR(B14="",C14=""),"",IF(COUNTIFS(재료목록!$A$2:$A$51,B14,재료목록!$B$2:$B$51,C14)>0,"OK","불일치")) -> OK
... A39: 45952 | B39: 붕어빵 | C39: 대봉투 | D39: 황금잉어빵세종 | E39: 1 | F39: 2200 | G39: =IF(OR(E39="",F39=""),"",E39*F39) -> 2200 | I39: =IF(OR(B39="",C39=""),"",IF(COUNTIFS(재료목록!$A$2:$A$51,B39,재료목록!$B$2:$B$51,C39)>0,"OK","불일치")) -> OK
A40: 45954 | B40: 닭강정 | C40: 몬스터 강정파우더 | D40: 소스몬스터 | E40: 2 | F40: 42500 | G40: =IF(OR(E40="",F40=""),"",E40*F40) -> 85000 | H40: 10KG | I40: =IF(OR(B40="",C40=""),"",IF(COUNTIFS(재료목록!$A$2:$A$51,B40,재료목록!$B$2:$B$51,C40)>0,"OK","불일치")) -> OK
A41: 45954 | B41: 닭강정 | C41: 몬스터 골드강정소스(골드간장) | D41: 소스몬스터 | E41: 3 | F41: 55500 | G41: =IF(OR(E41="",F41=""),"",E41*F41) -> 166500 | H41: 9kg/1box(3kg*3팩) | I41: =IF(OR(B41="",C41=""),"",IF(COUNTIFS(재료목록!$A$2:$A$51,B41,재료목록!$B$2:$B$51,C41)>0,"OK","불일치")) -> OK
A42: 45954 | B42: 떡볶이 | C42: 떡볶이 소스 | D42: 소스히어로 | E42: 2 | F42: 46000 | G42: =IF(OR(E42="",F42=""),"",E42*F42) -> 92000 | I42: =IF(OR(B42="",C42=""),"",IF(COUNTIFS(재료목록!$A$2:$A$51,B42,재료목록!$B$2:$B$51,C42)>0,"OK","불일치")) -> OK
A43: 45954 | B43: 붕어빵 | C43: 반죽 | D43: 황금잉어빵세종 | E43: 3 | F43: 13000 | G43: =IF(OR(E43="",F43=""),"",E43*F43) -> 39000 | I43: =IF(OR(B43="",C43=""),"",IF(COUNTIFS(재료목록!$A$2:$A$51,B43,재료목록!$B$2:$B$51,C43)>0,"OK","불일치")) -> OK
A44: 45954 | B44: 붕어빵 | C44: 팥 | D44: 황금잉어빵세종 | E44: 1 | F44: 8500 | G44: =IF(OR(E44="",F44=""),"",E44*F44) -> 8500 | I44: =IF(OR(B44="",C44=""),"",IF(COUNTIFS(재료목록!$A$2:$A$51,B44,재료목록!$B$2:$B$51,C44)>0,"OK","불일치")) -> OK
A45: 45954 | B45: 붕어빵 | C45: 슈크림 | D45: 황금잉어빵세종 | E45: 2 | F45: 8500 | G45: =IF(OR(E45="",F45=""),"",E45*F45) -> 17000 | I45: =IF(OR(B45="",C45=""),"",IF(COUNTIFS(재료목록!$A$2:$A$51,B45,재료목록!$B$2:$B$51,C45)>0,"OK","불일치")) -> OK
A46: 45954 | B46: 떡볶이 | C46: 쌀떡볶이 | D46: 농민식품 | E46: 2 | F46: 8000 | G46: =IF(OR(E46="",F46=""),"",E46*F46) -> 16000 | I46: =IF(OR(B46="",C46=""),"",IF(COUNTIFS(재료목록!$A$2:$A$51,B46,재료목록!$B$2:$B$51,C46)>0,"OK","불일치")) -> OK
A47: 45955 | B47: 붕어빵 | C47: 반죽 | D47: 황금잉어빵세종 | E47: 1 | F47: 13000 | G47: =IF(OR(E47="",F47=""),"",E47*F47) -> 13000 | I47: =IF(OR(B47="",C47=""),"",IF(COUNTIFS(재료목록!$A$2:$A$51,B47,재료목록!$B$2:$B$51,C47)>0,"OK","불일치")) -> OK
A48: 45955 | B48: 붕어빵 | C48: 슈크림 | D48: 황금잉어빵세종 | E48: 1 | F48: 8500 | G48: =IF(OR(E48="",F48=""),"",E48*F48) -> 8500 | I48: =IF(OR(B48="",C48=""),"",IF(COUNTIFS(재료목록!$A$2:$A$51,B48,재료목록!$B$2:$B$51,C48)>0,"OK","불일치")) -> OK
A49: 45957 | B49: 꼬치오뎅 | C49: 어묵용 스프 | D49: 미도몰 | E49: 5 | F49: 3200 | G49: =IF(OR(E49="",F49=""),"",E49*F49) -> 16000 | H49: (대용량) 300g | I49: =IF(OR(B49="",C49=""),"",IF(COUNTIFS(재료목록!$A$2:$A$51,B49,재료목록!$B$2:$B$51,C49)>0,"OK","불일치")) -> OK
A50: 45957 | B50: 꼬치오뎅 | C50: 가래떡 | D50: 미도몰 | E50: 3 | F50: 2800 | G50: =IF(OR(E50="",F50=""),"",E50*F50) -> 8400 | H50: 650g 10개들이 | I50: =IF(OR(B50="",C50=""),"",IF(COUNTIFS(재료목록!$A$2:$A$51,B50,재료목록!$B$2:$B$51,C50)>0,"OK","불일치")) -> OK
A51: 45957 | B51: 붕어빵 | C51: 반죽 | D51: 황금잉어빵세종 | E51: 2 | F51: 13000 | G51: =IF(OR(E51="",F51=""),"",E51*F51) -> 26000 | I51: =IF(OR(B51="",C51=""),"",IF(COUNTIFS(재료목록!$A$2:$A$51,B51,재료목록!$B$2:$B$51,C51)>0,"OK","불일치")) -> OK
A52: 45957 | B52: 붕어빵 | C52: 슈크림 | D52: 황금잉어빵세종 | E52: 1 | F52: 8500 | G52: =IF(OR(E52="",F52=""),"",E52*F52) -> 8500 | I52: =IF(OR(B52="",C52=""),"",IF(COUNTIFS(재료목록!$A$2:$A$51,B52,재료목록!$B$2:$B$51,C52)>0,"OK","불일치")) -> OK
A53: 45957 | B53: 붕어빵 | C53: 대봉투 | D53: 황금잉어빵세종 | E53: 2 | F53: 2200 | G53: =IF(OR(E53="",F53=""),"",E53*F53) -> 4400 | I53: =IF(OR(B53="",C53=""),"",IF(COUNTIFS(재료목록!$A$2:$A$51,B53,재료목록!$B$2:$B$51,C53)>0,"OK","불일치")) -> OK
A54: 45958 | B54: 닭강정 | C54: 해바라기씨유 | D54: 가보유통 | E54: 2 | F54: 48000 | G54: =IF(OR(E54="",F54=""),"",E54*F54) -> 96000 | I54: =IF(OR(B54="",C54=""),"",IF(COUNTIFS(재료목록!$A$2:$A$51,B54,재료목록!$B$2:$B$51,C54)>0,"OK","불일치")) -> OK
A55: 45958 | B55: 닭강정 | C55: 폐유 | D55: 가보유통 | E55: 1 | F55: -23000 | G55: =IF(OR(E55="",F55=""),"",E55*F55) -> -23000 | I55: =IF(OR(B55="",C55=""),"",IF(COUNTIFS(재료목록!$A$2:$A$51,B55,재료목록!$B$2:$B$51,C55)>0,"OK","불일치")) -> OK
A56: 45958 | B56: 붕어빵 | C56: 반죽 | D56: 황금잉어빵세종 | E56: 2 | F56: 13000 | G56: =IF(OR(E56="",F56=""),"",E56*F56) -> 26000 | I56: =IF(OR(B56="",C56=""),"",IF(COUNTIFS(재료목록!$A$2:$A$51,B56,재료목록!$B$2:$B$51,C56)>0,"OK","불일치")) -> OK
A57: 45958 | B57: 붕어빵 | C57: 팥 | D57: 황금잉어빵세종 | E57: 1 | F57: 8500 | G57: =IF(OR(E57="",F57=""),"",E57*F57) -> 8500 | I57: =IF(OR(B57="",C57=""),"",IF(COUNTIFS(재료목록!$A$2:$A$51,B57,재료목록!$B$2:$B$51,C57)>0,"OK","불일치")) -> OK
A58: 45958 | B58: 붕어빵 | C58: 슈크림 | D58: 황금잉어빵세종 | E58: 2 | F58: 8500 | G58: =IF(OR(E58="",F58=""),"",E58*F58) -> 17000 | I58: =IF(OR(B58="",C58=""),"",IF(COUNTIFS(재료목록!$A$2:$A$51,B58,재료목록!$B$2:$B$51,C58)>0,"OK","불일치")) -> OK
A59: 45961 | B59: 붕어빵 | C59: LPG가스 | D59: 시내가스 | E59: 1 | F59: 48000 | G59: =IF(OR(E59="",F59=""),"",E59*F59) -> 48000 | I59: =IF(OR(B59="",C59=""),"",IF(COUNTIFS(재료목록!$A$2:$A$51,B59,재료목록!$B$2:$B$51,C59)>0,"OK","불일치")) -> OK
A60: 45961 | B60: 붕어빵 | C60: 반죽 | D60: 황금잉어빵세종 | E60: 3 | F60: 13000 | G60: =IF(OR(E60="",F60=""),"",E60*F60) -> 39000 | I60: =IF(OR(B60="",C60=""),"",IF(COUNTIFS(재료목록!$A$2:$A$51,B60,재료목록!$B$2:$B$51,C60)>0,"OK","불일치")) -> OK
A61: 45961 | B61: 붕어빵 | C61: 팥 | D61: 황금잉어빵세종 | E61: 1 | F61: 8500 | G61: =IF(OR(E61="",F61=""),"",E61*F61) -> 8500 | I61: =IF(OR(B61="",C61=""),"",IF(COUNTIFS(재료목록!$A$2:$A$51,B61,재료목록!$B$2:$B$51,C61)>0,"OK","불일치")) -> OK
A62: 45961 | B62: 붕어빵 | C62: 슈크림 | D62: 황금잉어빵세종 | E62: 1 | F62: 8500 | G62: =IF(OR(E62="",F62=""),"",E62*F62) -> 8500 | I62: =IF(OR(B62="",C62=""),"",IF(COUNTIFS(재료목록!$A$2:$A$51,B62,재료목록!$B$2:$B$51,C62)>0,"OK","불일치")) -> OK
A63: 45962 | B63: 꼬치오뎅 | C63: 상천어묵 | D63: 미도어묵 대전지사 | E63: 20 | F63: 4700 | G63: =IF(OR(E63="",F63=""),"",E63*F63) -> 94000 | H63: 800g | I63: =IF(OR(B63="",C63=""),"",IF(COUNTIFS(재료목록!$A$2:$A$51,B63,재료목록!$B$2:$B$51,C63)>0,"OK","불일치")) -> OK
A64: 45962 | B64: 붕어빵 | C64: 반죽 | D64: 황금잉어빵세종 | E64: 2 | F64: 13000 | G64: =IF(OR(E64="",F64=""),"",E64*F64) -> 26000 | I64: =IF(OR(B64="",C64=""),"",IF(COUNTIFS(재료목록!$A$2:$A$51,B64,재료목록!$B$2:$B$51,C64)>0,"OK","불일치")) -> OK
...

Sheet 판매수량_기록
A1: 날짜 | B1: 닭강정_컵 | C1: 닭강정_박스(소) | D1: 닭강정_박스(중) | E1: 떡볶이_소 | F1: 떡볶이_중 | G1: 꼬치오뎅_꼬치 | H1: 붕어빵_팥 | I1: 붕어빵_슈크림 | J1: 붕어빵_치즈 | K1: 비고
A2: 45919 | H2: 3 | I2: 3
A3: 45920 | H3: 2 | I3: 1
A4: 45922 | H4: 7 | I4: 11
A5: 45923 | H5: 13 | I5: 17
A6: 45924 | H6: 6 | I6: 24
A7: 45925 | H7: 21 | I7: 42
A8: 45926 | H8: 22 | I8: 23
A9: 45927 | H9: 22 | I9: 8
A10: 45929 | H10: 31 | I10: 44
A11: 45930 | H11: 48 | I11: 35
A12: 45931 | H12: 37 | I12: 44
A13: 45932 | H13: 34 | I13: 32
... A57: 45990 | H57: 105 | I57: 67
A58: 45992 | B58: 25 | C58: 3 | D58: 1 | E58: 11 | F58: 1 | G58: 32 | H58: 35 | I58: 68
A59: 45993 | B59: 27 | C59: 4 | E59: 9 | F59: 7 | G59: 30 | H59: 73 | I59: 81
A60: 45994 | B60: 13 | C60: 4 | E60: 10 | F60: 4 | G60: 23 | H60: 61 | I60: 104
A61: 45995 | B61: 18 | C61: 2 | D61: 1 | E61: 6 | F61: 8 | G61: 26 | H61: 45 | I61: 61
A62: 45996 | B62: 11 | C62: 1 | D62: 2 | E62: 3 | F62: 4 | G62: 11 | H62: 126 | I62: 118
A63: 45997 | B63: 8 | C63: 1 | D63: 2 | E63: 3 | F63: 9 | G63: 21 | H63: 87 | I63: 126
A64: 45999 | B64: 17 | C64: 7 | E64: 7 | F64: 4 | G64: 29 | H64: 76 | I64: 108
A65: 46000 | B65: 18 | E65: 8 | G65: 15 | H65: 48 | I65: 77
A66: 46001 | B66: 15 | C66: 2 | E66: 9 | F66: 4 | G66: 31 | H66: 107 | I66: 122
A67: 46002 | B67: 25 | C67: 2 | E67: 18 | F67: 4 | G67: 39 | H67: 97 | I67: 85
A68: 46003 | B68: 16 | C68: 6 | D68: 1 | E68: 3 | F68: 4 | G68: 28 | H68: 34 | I68: 57
A69: 46004 | B69: 10 | C69: 4 | D69: 1 | E69: 6 | F69: 2 | G69: 9 | H69: 52 | I69: 27
A70: 46006 | B70: 24 | C70: 2 | E70: 8 | F70: 6 | G70: 42 | H70: 47 | I70: 62
A71: 46007 | B71: 16 | C71: 4 | E71: 2 | F71: 6 | G71: 28 | H71: 55 | I71: 82
A72: 46008 | B72: 20 | C72: 3 | E72: 7 | F72: 1 | G72: 34 | H72: 18 | I72: 23
A73: 46009 | B73: 21 | C73: 4 | E73: 19 | F73: 4 | G73: 40 | H73: 56 | I73: 60
A74: 46010 | B74: 24 | C74: 2 | D74: 1 | E74: 12 | F74: 3 | G74: 30 | H74: 71 | I74: 118
A75: 46011 | B75: 7 | C75: 3 | D75: 1 | F75: 4 | G75: 24 | H75: 76 | I75: 56
A76: 46013 | B76: 15 | C76: 2 | E76: 13 | F76: 5 | G76: 29 | H76: 111 | I76: 92
A77: 46014 | B77: 5 | C77: 1 | D77: 1 | E77: 3 | F77: 2 | G77: 19 | H77: 22 | I77: 38
A78: 46015 | B78: 8 | C78: 4 | D78: 1 | E78: 3 | F78: 3 | G78: 14 | H78: 41 | I78: 52
A79: 46017 | B79: 15 | C79: 3 | E79: 4 | F79: 2 | G79: 18 | H79: 72 | I79: 103
A80: 46018 | B80: 3 | C80: 8 | D80: 1 | E80: 4 | F80: 3 | G80: 7 | H80: 88 | I80: 87
A81: 46020 | B81: 16 | C81: 3 | E81: 8 | F81: 7 | G81: 25 | H81: 44 | I81: 60 | J81: 5
A82: 46021 | B82: 23 | C82: 2 | E82: 6 | F82: 4 | G82: 30 | H82: 54 | I82: 61 | J82: 20
A83: 46022 | B83: 14 | C83: 3 | D83: 3 | E83: 2 | F83: 4 | G83: 18 | H83: 77 | I83: 70 | J83: 17
...

Sheet 환산계수
A1: SKU(판매단위) | B1: 메뉴 | C1: 기준단위 | D1: 환산계수(입력) | E1: 설명
A2: 닭강정_컵 | B2: 닭강정 | C2: 컵환산 | D2: 1 | E2: 기준(95g)
A3: 닭강정_박스(소) | B3: 닭강정 | C3: 컵환산 | D3: 2.84 | E3: 270g
A4: 닭강정_박스(중) | B4: 닭강정 | C4: 컵환산 | D4: 4.84 | E4: 460g
A5: 떡볶이_소 | B5: 떡볶이 | C5: 소환산 | D5: 1 | E5: 기준(떡12개)
A6: 떡볶이_중 | B6: 떡볶이 | C6: 소환산 | D6: 2 | E6: 떡 24개
A7: 꼬치오뎅_꼬치 | B7: 꼬치오뎅 | C7: 꼬치 | D7: 1 | E7: 기준
A8: 붕어빵_팥 | B8: 붕어빵 | C8: 개 | D8: 1 | E8: 기준
A9: 붕어빵_슈크림 | B9: 붕어빵 | C9: 개 | D9: 1 | E9: 기준
A10: 붕어빵_치즈 | B10: 붕어빵 | C10: 개 | D10: 1.5 | E10: 1개 1,000원

Sheet 기간요약
A1: 기간 요약 및 메뉴별 원가 계산
A3: 시작일 | B3: 45992
A4: 종료일 | B4: 46022
A6: 매입 요약 | F6: 공통 배분비율(%)
A7: 메뉴 | B7: 매입액(원) | C7: 공통배분액(원) | D7: 합계(원) | F7: 메뉴 | G7: 배분비율(%) | H7: 공통배분액(원) | I7: 배분합계
A8: 닭강정 | B8: =IF(SUM(매입현황_기록!$G$5:$G$561)=0,"",SUMIFS(매입현황_기록!$G$5:$G$561,매입현황_기록!$B$5:$B$561,"닭강정",매입현황_기록!$A$5:$A$561,">="&$B$3,매입현황_기록!$A$5:$A$561,"<="&$B$4)) -> 774000 | C8: =H8 -> 0 | D8: =B8+C8 -> 774000 | F8: 닭강정 | G8: 0.4 | H8: =$B$12*G8 -> 0 | I8: =SUM(G8:G11) -> 1
A9: 떡볶이 | B9: =IF(SUM(매입현황_기록!$G$5:$G$561)=0,"",SUMIFS(매입현황_기록!$G$5:$G$561,매입현황_기록!$B$5:$B$561,"떡볶이",매입현황_기록!$A$5:$A$561,">="&$B$3,매입현황_기록!$A$5:$A$561,"<="&$B$4)) -> 271000 | C9: =H9 -> 0 | D9: =B9+C9 -> 271000 | F9: 떡볶이 | G9: 0.25 | H9: =$B$12*G9 -> 0
A10: 꼬치오뎅 | B10: =IF(SUM(매입현황_기록!$G$5:$G$561)=0,"",SUMIFS(매입현황_기록!$G$5:$G$561,매입현황_기록!$B$5:$B$561,"꼬치오뎅",매입현황_기록!$A$5:$A$561,">="&$B$3,매입현황_기록!$A$5:$A$561,"<="&$B$4)) -> 194000 | C10: =H10 -> 0 | D10: =B10+C10 -> 194000 | F10: 꼬치오뎅 | G10: 0.2 | H10: =$B$12*G10 -> 0
A11: 붕어빵 | B11: =IF(SUM(매입현황_기록!$G$5:$G$561)=0,"",SUMIFS(매입현황_기록!$G$5:$G$561,매입현황_기록!$B$5:$B$561,"붕어빵",매입현황_기록!$A$5:$A$561,">="&$B$3,매입현황_기록!$A$5:$A$561,"<="&$B$4)) -> 904490 | C11: =H11 -> 0 | D11: =B11+C11 -> 904490 | F11: 붕어빵 | G11: 0.15 | H11: =$B$12*G11 -> 0
A12: 공통 | B12: =IF(SUM(매입현황_기록!$G$5:$G$561)=0,"",SUMIFS(매입현황_기록!$G$5:$G$561,매입현황_기록!$B$5:$B$561,"공통",매입현황_기록!$A$5:$A$561,">="&$B$3,매입현황_기록!$A$5:$A$561,"<="&$B$4)) -> 0 | C12: 0 | D12: =B12 -> 0
A14: 판매 요약(기준단위 환산 포함)
A15: SKU(판매단위) | B15: 메뉴 | C15: 기간 판매수량 | D15: 환산계수 | E15: 기준단위 환산수량
A16: 닭강정_컵 | B16: 닭강정 | C16: =IF(SUM(판매수량_기록!$B$2:$B$399)=0,"",SUMIFS(판매수량_기록!$B$2:$B$399,판매수량_기록!$A$2:$A$399,">="&$B$3,판매수량_기록!$A$2:$A$399,"<="&$B$4)) -> 414 | D16: =환산계수!$D$2 -> 1 | E16: =C16*D16 -> 414
A17: 닭강정_박스(소) | B17: 닭강정 | C17: =IF(SUM(판매수량_기록!$C$2:$C$399)=0,"",SUMIFS(판매수량_기록!$C$2:$C$399,판매수량_기록!$A$2:$A$399,">="&$B$3,판매수량_기록!$A$2:$A$399,"<="&$B$4)) -> 80 | D17: =환산계수!$D$3 -> 2.84 | E17: =C17*D17 -> 227.2
A18: 닭강정_박스(중) | B18: 닭강정 | C18: =IF(SUM(판매수량_기록!$D$2:$D$399)=0,"",SUMIFS(판매수량_기록!$D$2:$D$399,판매수량_기록!$A$2:$A$399,">="&$B$3,판매수량_기록!$A$2:$A$399,"<="&$B$4)) -> 16 | D18: =환산계수!$D$4 -> 4.84 | E18: =C18*D18 -> 77.44
A19: 떡볶이_소 | B19: 떡볶이 | C19: =IF(SUM(판매수량_기록!$E$2:$E$399)=0,"",SUMIFS(판매수량_기록!$E$2:$E$399,판매수량_기록!$A$2:$A$399,">="&$B$3,판매수량_기록!$A$2:$A$399,"<="&$B$4)) -> 184 | D19: =환산계수!$D$5 -> 1 | E19: =C19*D19 -> 184
A20: 떡볶이_중 | B20: 떡볶이 | C20: =IF(SUM(판매수량_기록!$F$2:$F$399)=0,"",SUMIFS(판매수량_기록!$F$2:$F$399,판매수량_기록!$A$2:$A$399,">="&$B$3,판매수량_기록!$A$2:$A$399,"<="&$B$4)) -> 105 | D20: =환산계수!$D$6 -> 2 | E20: =C20*D20 -> 210
A21: 꼬치오뎅_꼬치 | B21: 꼬치오뎅 | C21: =IF(SUM(판매수량_기록!$G$2:$G$399)=0,"",SUMIFS(판매수량_기록!$G$2:$G$399,판매수량_기록!$A$2:$A$399,">="&$B$3,판매수량_기록!$A$2:$A$399,"<="&$B$4)) -> 652 | D21: =환산계수!$D$7 -> 1 | E21: =C21*D21 -> 652
A22: 붕어빵_팥 | B22: 붕어빵 | C22: =IF(SUM(판매수량_기록!$H$2:$H$399)=0,"",SUMIFS(판매수량_기록!$H$2:$H$399,판매수량_기록!$A$2:$A$399,">="&$B$3,판매수량_기록!$A$2:$A$399,"<="&$B$4)) -> 1673 | D22: =환산계수!$D$8 -> 1 | E22: =C22*D22 -> 1673
A23: 붕어빵_슈크림 | B23: 붕어빵 | C23: =IF(SUM(판매수량_기록!$I$2:$I$399)=0,"",SUMIFS(판매수량_기록!$I$2:$I$399,판매수량_기록!$A$2:$A$399,">="&$B$3,판매수량_기록!$A$2:$A$399,"<="&$B$4)) -> 1998 | D23: =환산계수!$D$9 -> 1 | E23: =C23*D23 -> 1998
A24: 붕어빵_치즈 | B24: 붕어빵 | C24: =IF(SUM(판매수량_기록!$J$2:$J$399)=0,"",SUMIFS(판매수량_기록!$J$2:$J$399,판매수량_기록!$A$2:$A$399,">="&$B$3,판매수량_기록!$A$2:$A$399,"<="&$B$4)) -> 42 | D24: =환산계수!$D$10 -> 1.5 | E24: =C24*D24 -> 63
A27: 메뉴별 기준단위 판매량 및 평균원가
A28: 메뉴 | B28: 기준단위 판매량 | C28: 매입합계(공통포함) | D28: 기준단위당 원가 | E28: 판매가(입력) | F28: 마진율
A29: 닭강정 | B29: =SUMIFS($E$16:$E$24,$B$16:$B$24,"닭강정") -> 718.64 | C29: =$D$8 -> 774000 | D29: =IF(B29=0,"",C29/B29) -> 1077.0344 | E29: 2241563 | F29: =IFERROR( (E29 - (B29*D29)) / E29, "" ) -> 0.65470522
A30: 떡볶이 | B30: =SUMIFS($E$16:$E$24,$B$16:$B$24,"떡볶이") -> 394 | C30: =$D$9 -> 271000 | D30: =IF(B30=0,"",C30/B30) -> 687.81726 | E30: 686838 | F30: =IFERROR( (E30 - (B30*D30)) / E30, "" ) -> 0.60543825
A31: 꼬치오뎅 | B31: =SUMIFS($E$16:$E$24,$B$16:$B$24,"꼬치오뎅") -> 652 | C31: =$D$10 -> 194000 | D31: =IF(B31=0,"",C31/B31) -> 297.54601 | E31: 690357 | F31: =IFERROR( (E31 - (B31*D31)) / E31, "" ) -> 0.71898597
A32: 붕어빵 | B32: =SUMIFS($E$16:$E$24,$B$16:$B$24,"붕어빵") -> 3734 | C32: =$D$11 -> 904490 | D32: =IF(B32=0,"",C32/B32) -> 242.23085 | E32: 2457387 | F32: =IFERROR( (E32 - (B32*D32)) / E32, "" ) -> 0.63193018
A34: * '기준단위당 원가'는 [환산계수]로 환산한 기준단위(예: 닭강정=컵환산) 기준 평균원가입니다.
